Workbook

Sheet 説明
B1: 分光実験 データ整理（第1週：実験1・2／第2週：実験3-2・3-3・3-4）
B3: ■ シート構成
B4: ・実験結果：報告書 第4章の表1〜表6をまとめたもの。他シートを参照しているので，元データを直せば自動で変わる
B5: ・実験1_波長：Na・Hg・Cd の輝線から回折角 θ と波長 λ を計算し，文献値と比較
B6: ・実験2_屈折率：Cd 4色の最小偏角 δ0 → 屈折率 n，3回の平均，波長–屈折率のグラフ
B7: ・実験3-2_波長校正：Cd 掃引データ，4本のピーク同定，校正曲線 λ = A x² + B x + C，Cd スペクトルと校正曲線のグラフ
B8: ・実験3-3_分解能：緑線をスリット 0.1 mm / 1 mm で掃引，ピーク値と半値幅
B9: ・実験3-4_白色LED：LED 掃引データを波長に換算，スペクトルのグラフ，2 つの山の半値幅
B10: ・week_1：元のデータ（変更していません）
B11: ■ 色のルール
B12: ・青字＝手稿から転記した測定値／定数 ・黒字＝Excel の公式 ・緑＝ピーク ・黄色背景＝要確認
B13: ■ 主な結果
... B23: ・実験3-3 の背景 I_b：1 mm の掃引は x=605〜660 しかなく遠方の背景が測られていない。暫定値を入れてあるので，半値幅 11.7 nm には不確かさがある。

Sheet 実験結果
B1: 実験結果 （報告書の表1〜表8をそのまま）
B2: 報告書と同じ列・同じ並び・同じ桁数。数値は各シートを参照しているので、元データを直せばここも変わる。
B4: 表1 各ランプの輝線の波長
B5: ランプ | C5: 色 | D5: x1 左 [mm] | E5: x1 中 [mm] | F5: x1 右 [mm] | G5: x [mm] | H5: θ [deg] | I5: λ [nm] | J5: 文献値 [nm] | K5: 相対誤差 [%]
B6: Na | C6: オレンジ | D6: =IF('実験1_波長'!F12="","—",TEXT('実験1_波長'!F12,"0.0")) | E6: =IF('実験1_波長'!G12="","—",TEXT('実験1_波長'!G12,"0.0")) | F6: =IF('実験1_波長'!H12="","—",TEXT('実験1_波長'!H12,"0.0")) | G6: ='実験1_波長'!I12 | H6: ='実験1_波長'!J12 | I6: ='実験1_波長'!K12 | J6: ='実験1_波長'!L12 | K6: ='実験1_波長'!N12
B7: Hg | C7: オレンジ | D7: =IF('実験1_波長'!F14="","—",TEXT('実験1_波長'!F14,"0.0")) | E7: =IF('実験1_波長'!G14="","—",TEXT('実験1_波長'!G14,"0.0")) | F7: =IF('実験1_波長'!H14="","—",TEXT('実験1_波長'!H14,"0.0")) | G7: ='実験1_波長'!I14 | H7: ='実験1_波長'!J14 | I7: ='実験1_波長'!K14 | J7: ='実験1_波長'!L14 | K7: ='実験1_波長'!N14
B8: Hg | C8: 緑 | D8: =IF('実験1_波長'!F15="","—",TEXT('実験1_波長'!F15,"0.0")) | E8: =IF('実験1_波長'!G15="","—",TEXT('実験1_波長'!G15,"0.0")) | F8: =IF('実験1_波長'!H15="","—",TEXT('実験1_波長'!H15,"0.0")) | G8: ='実験1_波長'!I15 | H8: ='実験1_波長'!J15 | I8: ='実験1_波長'!K15 | J8: ='実験1_波長'!L15 | K8: ='実験1_波長'!N15
B9: Hg | C9: 青 | D9: =IF('実験1_波長'!F16="","—",TEXT('実験1_波長'!F16,"0.0")) | E9: =IF('実験1_波長'!G16="","—",TEXT('実験1_波長'!G16,"0.0")) | F9: =IF('実験1_波長'!H16="","—",TEXT('実験1_波長'!H16,"0.0")) | G9: ='実験1_波長'!I16 | H9: ='実験1_波長'!J16 | I9: ='実験1_波長'!K16 | J9: ='実験1_波長'!L16 | K9: ='実験1_波長'!N16
B10: Cd | C10: 赤 | D10: =IF('実験1_波長'!F17="","—",TEXT('実験1_波長'!F17,"0.0")) | E10: =IF('実験1_波長'!G17="","—",TEXT('実験1_波長'!G17,"0.0")) | F10: =IF('実験1_波長'!H17="","—",TEXT('実験1_波長'!H17,"0.0")) | G10: ='実験1_波長'!I17 | H10: ='実験1_波長'!J17 | I10: ='実験1_波長'!K17 | J10: ='実験1_波長'!L17 | K10: ='実験1_波長'!N17
B11: Cd | C11: 緑 | D11: =IF('実験1_波長'!F18="","—",TEXT('実験1_波長'!F18,"0.0")) | E11: =IF('実験1_波長'!G18="","—",TEXT('実験1_波長'!G18,"0.0")) | F11: =IF('実験1_波長'!H18="","—",TEXT('実験1_波長'!H18,"0.0")) | G11: ='実験1_波長'!I18 | H11: ='実験1_波長'!J18 | I11: ='実験1_波長'!K18 | J11: ='実験1_波長'!L18 | K11: ='実験1_波長'!N18
B12: Cd | C12: 水色 | D12: =IF('実験1_波長'!F19="","—",TEXT('実験1_波長'!F19,"0.0")) | E12: =IF('実験1_波長'!G19="","—",TEXT('実験1_波長'!G19,"0.0")) | F12: =IF('実験1_波長'!H19="","—",TEXT('実験1_波長'!H19,"0.0")) | G12: ='実験1_波長'!I19 | H12: ='実験1_波長'!J19 | I12: ='実験1_波長'!K19 | J12: ='実験1_波長'!L19 | K12: ='実験1_波長'!N19
B13: Cd | C13: 青 | D13: =IF('実験1_波長'!F20="","—",TEXT('実験1_波長'!F20,"0.0")) | E13: =IF('実験1_波長'!G20="","—",TEXT('実験1_波長'!G20,"0.0")) | F13: =IF('実験1_波長'!H20="","—",TEXT('実験1_波長'!H20,"0.0")) | G13: ='実験1_波長'!I20 | H13: ='実験1_波長'!J20 | I13: ='実験1_波長'!K20 | J13: ='実験1_波長'!L20 | K13: ='実験1_波長'!N20
B15: 表2 各スクリーン位置における最小偏角と屈折率
B16: 色 | C16: λ [nm] | D16: L [mm] | E16: x [mm] | F16: δ₀ [deg] | G16: n
B17: 赤 | C17: ='実験2_屈折率'!C8 | D17: ='実験2_屈折率'!D$6 | E17: ='実験2_屈折率'!D8 | F17: ='実験2_屈折率'!E8 | G17: ='実験2_屈折率'!F8
B18: 赤 | C18: ='実験2_屈折率'!C8 | D18: ='実験2_屈折率'!G$6 | E18: ='実験2_屈折率'!G8 | F18: ='実験2_屈折率'!H8 | G18: ='実験2_屈折率'!I8
B19: 赤 | C19: ='実験2_屈折率'!C8 | D19: ='実験2_屈折率'!J$6 | E19: ='実験2_屈折率'!J8 | F19: ='実験2_屈折率'!K8 | G19: ='実験2_屈折率'!L8
B20: 緑 | C20: ='実験2_屈折率'!C9 | D20: ='実験2_屈折率'!D$6 | E20: ='実験2_屈折率'!D9 | F20: ='実験2_屈折率'!E9 | G20: ='実験2_屈折率'!F9
B21: 緑 | C21: ='実験2_屈折率'!C9 | D21: ='実験2_屈折率'!G$6 | E21: ='実験2_屈折率'!G9 | F21: ='実験2_屈折率'!H9 | G21: ='実験2_屈折率'!I9
B22: 緑 | C22: ='実験2_屈折率'!C9 | D22: ='実験2_屈折率'!J$6 | E22: ='実験2_屈折率'!J9 | F22: ='実験2_屈折率'!K9 | G22: ='実験2_屈折率'!L9
B23: 水色 | C23: ='実験2_屈折率'!C10 | D23: ='実験2_屈折率'!D$6 | E23: ='実験2_屈折率'!D10 | F23: ='実験2_屈折率'!E10 | G23: ='実験2_屈折率'!F10
B24: 水色 | C24: ='実験2_屈折率'!C10 | D24: ='実験2_屈折率'!G$6 | E24: ='実験2_屈折率'!G10 | F24: ='実験2_屈折率'!H10 | G24: ='実験2_屈折率'!I10
B25: 水色 | C25: ='実験2_屈折率'!C10 | D25: ='実験2_屈折率'!J$6 | E25: ='実験2_屈折率'!J10 | F25: ='実験2_屈折率'!K10 | G25: ='実験2_屈折率'!L10
B26: 青 | C26: ='実験2_屈折率'!C11 | D26: ='実験2_屈折率'!D$6 | E26: ='実験2_屈折率'!D11 | F26: ='実験2_屈折率'!E11 | G26: ='実験2_屈折率'!F11
B27: 青 | C27: ='実験2_屈折率'!C11 | D27: ='実験2_屈折率'!G$6 | E27: ='実験2_屈折率'!G11 | F27: ='実験2_屈折率'!H11 | G27: ='実験2_屈折率'!I11
B28: 青 | C28: ='実験2_屈折率'!C11 | D28: ='実験2_屈折率'!J$6 | E28: ='実験2_屈折率'!J11 | F28: ='実験2_屈折率'!K11 | G28: ='実験2_屈折率'!L11
B30: 表3 屈折率の平均値
B31: 色 | C31: λ [nm] | D31: n（3 回の平均）
B32: 赤 | C32: ='実験2_屈折率'!C8 | D32: ='実験2_屈折率'!M8
B33: 緑 | C33: ='実験2_屈折率'!C9 | D33: ='実験2_屈折率'!M9
B34: 水色 | C34: ='実験2_屈折率'!C10 | D34: ='実験2_屈折率'!M10
B35: 青 | C35: ='実験2_屈折率'!C11 | D35: ='実験2_屈折率'!M11
B37: 表4 Cd ランプの輝線のピーク位置
B38: 色 | C38: ピーク位置 x [目盛] | D38: ピーク出力 [V] | E38: 文献波長 [nm]
B39: 赤 | C39: ='実験3-2_波長校正'!C6 | D39: ='実験3-2_波長校正'!D6 | E39: =TEXT('実験3-2_波長校正'!E6,"0.000") | G39: 校正には赤・緑・水色の3本を使った。青は2本の輝線が重なっているため使わなかった。
B40: 緑 | C40: ='実験3-2_波長校正'!C7 | D40: ='実験3-2_波長校正'!D7 | E40: =TEXT('実験3-2_波長校正'!E7,"0.000")
B41: 水色 | C41: ='実験3-2_波長校正'!C8 | D41: ='実験3-2_波長校正'!D8 | E41: =TEXT('実験3-2_波長校正'!E8,"0.000")
B42: 青 | C42: ='実験3-2_波長校正'!C9 | D42: ='実験3-2_波長校正'!D9 | E42: 466.235 / 467.815
B44: 表5 入射スリット幅とスペクトル幅（Cd 緑線 508.582 nm）
B45: 入射スリット幅 [mm] | C45: ピーク出力 [V] | D45: 半値幅 [nm]
...

Sheet 実験1_波長
B1: 実験1 各種ランプの輝線の波長（反射型回折格子・1次回折光）
B2: 式: tanθ = (x0 + x1) / L ， d sinθ = mλ（m = 1）。青字＝手稿から転記した入力値，黒字＝Excel公式，黄色＝要確認。
B4: 定数 | C4: 値 | D4: 単位 | E4: 出典
B5: 格子定数 d | C5: =10^6/1200 | D5: nm | E5: 講義 [装置/器具] 2-2: 刻線数 1200 lines/mm → d = 1/1200 mm
B6: 回折格子–スクリーン間距離 L | C6: 150 | D6: mm | E6: 手稿 第1週 p.2（L → 150 mm）
B7: x0（光軸の位置） | C7: 50 | D7: mm | E7: 手稿 第1週 p.2（x0 → 50 mm）
B8: 回折次数 m | C8: 1 | D8: － | E8: 手稿 第1週 p.1（m = +1 のみ）
B11: ランプ | C11: 輝線の色 | D11: x0 [mm] | E11: L [mm] | F11: x1 左 [mm] | G11: x1 中 [mm] | H11: x1 右 [mm] | I11: x = x0+x1 [mm] | J11: θ [deg] | K11: λ [nm] | L11: 文献値 [nm] | M11: λ − 文献値 [nm] | N11: 相対誤差 [%] | O11: 出典・備考
B12: Na | C12: オレンジ（報告書に使用） | D12: =$C$7 | E12: =$C$6 | F12: 95 | G12: 97 | H12: 99 | I12: =IF(COUNT(D12,E12,G12)=3,D12+G12,"") | J12: =IF(I12="","",DEGREES(ATAN(I12/E12))) | K12: =IF(J12="","",$C$5*SIN(RADIANS(J12))/$C$8) | L12: =AVERAGE(588.995,589.592) | M12: =IF(K12="","",K12-L12) | N12: =IF(K12="","",ABS(M12)/L12*100) | O12: 手稿 第1週 p.2。報告書にはこの組（95 / 97 / 99）を使う。文献値は D線2本(588.995, 589.592 nm)の平均
B13: Na | C13: オレンジ（参考・不使用） | D13: =$C$7 | E13: =$C$6 | F13: 95.2 | G13: 98.1 | H13: 100.4 | I13: =IF(COUNT(D13,E13,G13)=3,D13+G13,"") | J13: =IF(I13="","",DEGREES(ATAN(I13/E13))) | K13: =IF(J13="","",$C$5*SIN(RADIANS(J13))/$C$8) | L13: =AVERAGE(588.995,589.592) | M13: =IF(K13="","",K13-L13) | N13: =IF(K13="","",ABS(M13)/L13*100) | O13: 手稿 第1週 p.3 の再測定値。参考として残すが報告書には使わない
B14: Hg | C14: オレンジ | D14: =$C$7 | E14: =$C$6 | F14: 87.5 | G14: 89 | H14: 90.9 | I14: =IF(COUNT(D14,E14,G14)=3,D14+G14,"") | J14: =IF(I14="","",DEGREES(ATAN(I14/E14))) | K14: =IF(J14="","",$C$5*SIN(RADIANS(J14))/$C$8) | L14: 579.065 | M14: =IF(K14="","",K14-L14) | N14: =IF(K14="","",ABS(M14)/L14*100) | O14: 手稿 第1週 p.4。文献値 579.065 nm（講義 付録）
B15: Hg | C15: 緑 | D15: =$C$7 | E15: =$C$6 | F15: 74.2 | G15: 75.5 | H15: 77 | I15: =IF(COUNT(D15,E15,G15)=3,D15+G15,"") | J15: =IF(I15="","",DEGREES(ATAN(I15/E15))) | K15: =IF(J15="","",$C$5*SIN(RADIANS(J15))/$C$8) | L15: 546.074 | M15: =IF(K15="","",K15-L15) | N15: =IF(K15="","",ABS(M15)/L15*100) | O15: 手稿 第1週 p.4。文献値 546.074 nm（講義 付録）
B16: Hg | C16: 青 | D16: =$C$7 | E16: =$C$6 | F16: 37.1 | G16: 38.2 | H16: 39.2 | I16: =IF(COUNT(D16,E16,G16)=3,D16+G16,"") | J16: =IF(I16="","",DEGREES(ATAN(I16/E16))) | K16: =IF(J16="","",$C$5*SIN(RADIANS(J16))/$C$8) | L16: 435.835 | M16: =IF(K16="","",K16-L16) | N16: =IF(K16="","",ABS(M16)/L16*100) | O16: 手稿 第1週 p.4。文献値 435.835 nm（講義 付録）
B17: Cd | C17: 赤 | D17: =$C$7 | E17: =$C$6 | G17: 12.5 | I17: =IF(COUNT(D17,E17,G17)=3,D17+G17,"") | J17: =IF(I17="","",DEGREES(ATAN(I17/E17))) | K17: =IF(J17="","",$C$5*SIN(RADIANS(J17))/$C$8) | L17: 643.847 | M17: =IF(K17="","",K17-L17) | N17: =IF(K17="","",ABS(M17)/L17*100) | O17: 手稿 第1週 p.5「真ん中 12.5 mm」。左右は読み取りにくく中心のみ。x0・L は Na と同じとした。計算値は文献値の約半分で外れ値
B18: Cd | C18: 緑 | D18: =$C$7 | E18: =$C$6 | F18: 52 | G18: 54.5 | H18: 57 | I18: =IF(COUNT(D18,E18,G18)=3,D18+G18,"") | J18: =IF(I18="","",DEGREES(ATAN(I18/E18))) | K18: =IF(J18="","",$C$5*SIN(RADIANS(J18))/$C$8) | L18: 508.582 | M18: =IF(K18="","",K18-L18) | N18: =IF(K18="","",ABS(M18)/L18*100) | O18: 手稿 第1週 p.5。x0・L は Na と同じとした
B19: Cd | C19: 水色 | D19: =$C$7 | E19: =$C$6 | F19: 35.5 | G19: 37 | H19: 40.5 | I19: =IF(COUNT(D19,E19,G19)=3,D19+G19,"") | J19: =IF(I19="","",DEGREES(ATAN(I19/E19))) | K19: =IF(J19="","",$C$5*SIN(RADIANS(J19))/$C$8) | L19: 479.992 | M19: =IF(K19="","",K19-L19) | N19: =IF(K19="","",ABS(M19)/L19*100) | O19: 手稿 第1週 p.5。x0・L は Na と同じとした
B20: Cd | C20: 青 | D20: =$C$7 | E20: =$C$6 | F20: 35.6 | I20: =IF(COUNT(D20,E20,F20)=3,D20+F20,"") | J20: =IF(I20="","",DEGREES(ATAN(I20/E20))) | K20: =IF(J20="","",$C$5*SIN(RADIANS(J20))/$C$8) | L20: 467.815 | M20: =IF(K20="","",K20-L20) | N20: =IF(K20="","",ABS(M20)/L20*100) | O20: 手稿 第1週 p.5「青 左 35.6」のみ。光が細く中・右は読み取れなかった。λ は左端の値で計算。第2週の結果より，この輝線は 466.235 と 467.815 nm の未分解の重なりと分かった

Sheet 実験2_屈折率
B1: 実験2 最小偏角 δ0 とプリズム（ガラス）の屈折率
B2: 式: tanδ0 = L / x ， n = sin{(δ0 + α)/2} / sin(α/2)（講義 式(4)）。青字＝手稿から転記，黒字＝公式。
B4: 頂角 α | C4: 60 | D4: deg | E4: 講義 [装置/器具] 2-1: プリズムは正三角形，頂角 α = 60°
B6: 色 | C6: 波長 λ [nm] | D6: 150 | G6: 175 | J6: 200 | M6: n 平均 （3回） | N6: 出典・備考
D7: x [mm] | E7: δ0 [deg] | F7: n | G7: x [mm] | H7: δ0 [deg] | I7: n | J7: x [mm] | K7: δ0 [deg] | L7: n
B8: 赤 | C8: 643.847 | D8: 136 | E8: =DEGREES(ATAN(D$6/D8)) | F8: =SIN(RADIANS((E8+$C$4)/2))/SIN(RADIANS($C$4/2)) | G8: 155 | H8: =DEGREES(ATAN(G$6/G8)) | I8: =SIN(RADIANS((H8+$C$4)/2))/SIN(RADIANS($C$4/2)) | J8: 188 | K8: =DEGREES(ATAN(J$6/J8)) | L8: =SIN(RADIANS((K8+$C$4)/2))/SIN(RADIANS($C$4/2)) | M8: =AVERAGE(F8,I8,L8) | N8: Cd 赤 643.847 nm（講義 付録）。x は手稿 第1週 p.6
B9: 緑 | C9: 508.582 | D9: 128 | E9: =DEGREES(ATAN(D$6/D9)) | F9: =SIN(RADIANS((E9+$C$4)/2))/SIN(RADIANS($C$4/2)) | G9: 151 | H9: =DEGREES(ATAN(G$6/G9)) | I9: =SIN(RADIANS((H9+$C$4)/2))/SIN(RADIANS($C$4/2)) | J9: 181 | K9: =DEGREES(ATAN(J$6/J9)) | L9: =SIN(RADIANS((K9+$C$4)/2))/SIN(RADIANS($C$4/2)) | M9: =AVERAGE(F9,I9,L9) | N9: Cd 緑 508.582 nm。x は手稿 第1週 p.6
B10: 水色 | C10: 479.992 | D10: 127 | E10: =DEGREES(ATAN(D$6/D10)) | F10: =SIN(RADIANS((E10+$C$4)/2))/SIN(RADIANS($C$4/2)) | G10: 149 | H10: =DEGREES(ATAN(G$6/G10)) | I10: =SIN(RADIANS((H10+$C$4)/2))/SIN(RADIANS($C$4/2)) | J10: 176 | K10: =DEGREES(ATAN(J$6/J10)) | L10: =SIN(RADIANS((K10+$C$4)/2))/SIN(RADIANS($C$4/2)) | M10: =AVERAGE(F10,I10,L10) | N10: Cd 水色 479.992 nm。x は手稿 第1週 p.6
B11: 青 | C11: 467.815 | D11: 118 | E11: =DEGREES(ATAN(D$6/D11)) | F11: =SIN(RADIANS((E11+$C$4)/2))/SIN(RADIANS($C$4/2)) | G11: 143 | H11: =DEGREES(ATAN(G$6/G11)) | I11: =SIN(RADIANS((H11+$C$4)/2))/SIN(RADIANS($C$4/2)) | J11: 170 | K11: =DEGREES(ATAN(J$6/J11)) | L11: =SIN(RADIANS((K11+$C$4)/2))/SIN(RADIANS($C$4/2)) | M11: =AVERAGE(F11,I11,L11) | N11: Cd 青 467.815 nm（466.235 nm との未分解の重なり）。x は手稿 第1週 p.6
B32: ※ 図名は図の下に付ける。横軸 440–680 nm，縦軸 1.60–1.68 に固定。

Sheet 実験3-2_波長校正
B1: 実験3-2 Cd ランプのスペクトル測定と波長校正
B2: x はマイクロメータ読み（1 目盛 = 0.01 mm，1 回転 = 0.5 mm）。回転ステージ角は θr = k x + α と書けるので，式(10) に代入すると λ = A x² + B x + C（講義 式(10)＋授業の板書）。青字＝手稿から転記，黒字＝Excel公式，緑＝ピーク，黄色＝要確認。
B3: 入射スリット幅 0.1 mm（手稿 第2週 p.4 見出し「幅 0.1mm」）。λ が x とともに減少することに注意。
B5: 輝線の色 | C5: x ピーク | D5: I ピーク [V] | E5: 文献波長 [nm] | F5: 校正に使用 | G5: 備考
B6: 赤 | C6: =AVERAGE(278,279) | D6: 0.007 | E6: 643.847 | F6: ○ | G6: x=278,279 が同値（0.0070）のため中点を採用
B7: 緑 | C7: 634 | D7: 0.0089 | E7: 508.582 | F7: ○ | G7: スリットで緑色を目視確認（手稿の「←緑」の書き込み）。4本中で最も強い → 実験3-3 に使用
B8: 水色 | C8: 705 | D8: 0.0075 | E8: 479.992 | F8: ○
B9: 青 | C9: 738 | D9: 0.0059 | E9: 467.815 | F9: × | G9: 466.235 nm と 467.815 nm（間隔 1.58 nm）の未分解の重なり。分解能 4.4 nm より狭いため分離できない。校正には使わず検証のみ
B11: 校正曲線 λ = A x² + B x + C
B12: A [nm/目盛²] | C12: =INDEX(LINEST($E$6:$E$8,$C$6:$C$8^{1,2}),1,1) | D12: LINEST による最小二乗フィット（赤・緑・水色の3点，未知数3個なので厳密に一致）。
B13: B [nm/目盛] | C13: =INDEX(LINEST($E$6:$E$8,$C$6:$C$8^{1,2}),1,2)
B14: C [nm] | C14: =INDEX(LINEST($E$6:$E$8,$C$6:$C$8^{1,2}),1,3)
B15: 検証
B16: x = 738 の λ | C16: =$C$12*738^2+$C$13*738+$C$14 | D16: nm | E16: 実測の弱いピーク。467.815 と 466.235 nm の中間に出る → 未分解の重なりの証拠
B17: λ = 467.815 nm の x | C17: =(-$C$13-SQRT($C$13^2-4*$C$12*($C$14-467.815)))/(2*$C$12) | D17: 目盛
B18: λ = 466.235 nm の x | C18: =(-$C$13-SQRT($C$13^2-4*$C$12*($C$14-466.235)))/(2*$C$12) | D18: 目盛
I19: 校正曲線描画用
B21: x [目盛] | C21: I [V] | D21: λ [nm] | E21: 掃引 | I21: x [目盛] | J21: λ_fit [nm]
B22: 250 | C22: 0.0048 | D22: =$C$12*B22^2+$C$13*B22+$C$14 | E22: 1回目（赤線のみ） | I22: 200 | J22: =$C$12*I22^2+$C$13*I22+$C$14
B23: 255 | C23: 0.005 | D23: =$C$12*B23^2+$C$13*B23+$C$14 | E23: 1回目（赤線のみ） | I23: 220 | J23: =$C$12*I23^2+$C$13*I23+$C$14
B24: 260 | C24: 0.0051 | D24: =$C$12*B24^2+$C$13*B24+$C$14 | E24: 1回目（赤線のみ） | I24: 240 | J24: =$C$12*I24^2+$C$13*I24+$C$14
B25: 265 | C25: 0.0051 | D25: =$C$12*B25^2+$C$13*B25+$C$14 | E25: 1回目（赤線のみ） | I25: 260 | J25: =$C$12*I25^2+$C$13*I25+$C$14
B26: 270 | C26: 0.0053 | D26: =$C$12*B26^2+$C$13*B26+$C$14 | E26: 1回目（赤線のみ） | I26: 280 | J26: =$C$12*I26^2+$C$13*I26+$C$14
B27: 275 | C27: 0.0059 | D27: =$C$12*B27^2+$C$13*B27+$C$14 | E27: 1回目（赤線のみ） | I27: 300 | J27: =$C$12*I27^2+$C$13*I27+$C$14
B28: 280 | C28: 0.0065 | D28: =$C$12*B28^2+$C$13*B28+$C$14 | E28: 1回目（赤線のみ） | I28: 320 | J28: =$C$12*I28^2+$C$13*I28+$C$14
B29: 282 | C29: 0.0063 | D29: =$C$12*B29^2+$C$13*B29+$C$14 | E29: 1回目（赤線のみ） | I29: 340 | J29: =$C$12*I29^2+$C$13*I29+$C$14
B30: 284 | C30: 0.0059 | D30: =$C$12*B30^2+$C$13*B30+$C$14 | E30: 1回目（赤線のみ） | I30: 360 | J30: =$C$12*I30^2+$C$13*I30+$C$14
B31: 286 | C31: 0.0058 | D31: =$C$12*B31^2+$C$13*B31+$C$14 | E31: 1回目（赤線のみ） | I31: 380 | J31: =$C$12*I31^2+$C$13*I31+$C$14
B32: 288 | C32: 0.0056 | D32: =$C$12*B32^2+$C$13*B32+$C$14 | E32: 1回目（赤線のみ） | I32: 400 | J32: =$C$12*I32^2+$C$13*I32+$C$14
B33: 290 | C33: 0.0055 | D33: =$C$12*B33^2+$C$13*B33+$C$14 | E33: 1回目（赤線のみ） | I33: 420 | J33: =$C$12*I33^2+$C$13*I33+$C$14
... B55: 277 | C55: 0.0069 | D55: =$C$12*B55^2+$C$13*B55+$C$14 | E55: 2回目（本掃引） | I55: 860 | J55: =$C$12*I55^2+$C$13*I55+$C$14
B56: 278 | C56: 0.007 | D56: =$C$12*B56^2+$C$13*B56+$C$14 | E56: 2回目（本掃引）
B57: 279 | C57: 0.007 | D57: =$C$12*B57^2+$C$13*B57+$C$14 | E57: 2回目（本掃引）
B58: 280 | C58: 0.0069 | D58: =$C$12*B58^2+$C$13*B58+$C$14 | E58: 2回目（本掃引）
B59: 281 | C59: 0.0067 | D59: =$C$12*B59^2+$C$13*B59+$C$14 | E59: 2回目（本掃引）
B60: 282 | C60: 0.0065 | D60: =$C$12*B60^2+$C$13*B60+$C$14 | E60: 2回目（本掃引）
B61: 283 | C61: 0.0063 | D61: =$C$12*B61^2+$C$13*B61+$C$14 | E61: 2回目（本掃引）
B62: 284 | C62: 0.0062 | D62: =$C$12*B62^2+$C$13*B62+$C$14 | E62: 2回目（本掃引）
B63: 285 | C63: 0.0061 | D63: =$C$12*B63^2+$C$13*B63+$C$14 | E63: 2回目（本掃引）
B64: 286 | C64: 0.006 | D64: =$C$12*B64^2+$C$13*B64+$C$14 | E64: 2回目（本掃引）
...

Sheet 実験3-3_分解能
B1: 実験3-3 スペクトル分解能測定（Cd 緑線 508.582 nm）
B2: 実験3-2 で最も強かった緑線について，入射スリット幅を変えて同じ輝線を掃引した。半値幅は背景を差し引いた最大値の 1/2 の高さでの幅（線形内挿）。λ は実験3-2 の校正曲線で換算。
B3: 黄色＝要確認。1 mm のデータは x=605〜660 しか無く，背景（遠方のベースライン）が測られていない。
B5: x [目盛] | C5: I [V]（0.1 mm） | E5: x [目盛] | F5: I [V]（1 mm） | H5: 解析
B6: 625 | C6: 0.0059 | E6: 605 | F6: 0.0066 | H6: 項目 | I6: スリット 0.1 mm | J6: スリット 1 mm
B7: 626 | C7: 0.0062 | E7: 610 | F7: 0.0072 | H7: 背景 I_b [V] | I7: 0.0049 | J7: 0.0067 | K7: 0.1 mm は x=500〜600 の平坦部。1 mm は掃引両端(605, 660)の平均 → 遠方の背景は未測定なので暫定値
B8: 627 | C8: 0.0065 | E8: 615 | F8: 0.0082 | H8: ピーク I_p [V] | I8: =MAX($C$6:$C$36) | J8: =MAX($F$6:$F$17)
B9: 628 | C9: 0.0069 | E9: 620 | F9: 0.0123 | H9: ピーク位置 x_p [目盛] | I9: =INDEX($B$6:$B$36,MATCH(I8,$C$6:$C$36,0)) | J9: =INDEX($E$6:$E$17,MATCH(J8,$F$6:$F$17,0))
B10: 629 | C10: 0.0074 | E10: 625 | F10: 0.0148 | H10: 半値 I_h [V] | I10: =I7+(I8-I7)/2 | J10: =J7+(J8-J7)/2
B11: 630 | C11: 0.008 | E11: 630 | F11: 0.0159 | H11: 左交点 x_L [目盛] | I11: =B8+(I10-C8)*(B9-B8)/(C9-C8) | J11: =E8+(J10-F8)*(E9-E8)/(F9-F8) | K11: 線形内挿の区間：0.1mm は x=627→628，1mm は x=615→620。交点は読み取りの刻み幅のため ±1 目盛（約 0.4 nm）の不確かさがある
B12: 631 | C12: 0.0081 | E12: 635 | F12: 0.0162 | H12: 右交点 x_R [目盛] | I12: =B19+(I10-C19)*(B20-B19)/(C20-C19) | J12: =E14+(J10-F14)*(E15-E14)/(F15-F14) | K12: 線形内挿の区間：0.1mm は x=638→639，1mm は x=645→650。0.1mm では x=639 と 640 が同値のため右交点には ±1 目盛の幅がある
B13: 632 | C13: 0.0083 | E13: 640 | F13: 0.0156 | H13: 半値幅 Δx [目盛] | I13: =I12-I11 | J13: =J12-J11
B14: 633 | C14: 0.0082 | E14: 645 | F14: 0.0132 | H14: 半値幅 Δλ [nm] | I14: =ABS(('実験3-2_波長校正'!C$12*I11^2+'実験3-2_波長校正'!C$13*I11+'実験3-2_波長校正'!C$14)-('実験3-2_波長校正'!C$12*I12^2+'実験3-2_波長校正'!C$13*I12+'実験3-2_波長校正'!C$14)) | J14: =ABS(('実験3-2_波長校正'!C$12*J11^2+'実験3-2_波長校正'!C$13*J11+'実験3-2_波長校正'!C$14)-('実験3-2_波長校正'!C$12*J12^2+'実験3-2_波長校正'!C$13*J12+'実験3-2_波長校正'!C$14))
B15: 634 | C15: 0.0089 | E15: 650 | F15: 0.0104 | H15: ピーク波長 [nm] | I15: ='実験3-2_波長校正'!C$12*I9^2+'実験3-2_波長校正'!C$13*I9+'実験3-2_波長校正'!C$14 | J15: ='実験3-2_波長校正'!C$12*J9^2+'実験3-2_波長校正'!C$13*J9+'実験3-2_波長校正'!C$14
B16: 635 | C16: 0.0077 | E16: 655 | F16: 0.0082
B17: 636 | C17: 0.0074 | E17: 660 | F17: 0.0068 | H17: まとめ（報告書の表）
B18: 637 | C18: 0.0073 | H18: 入射スリット幅 [µm] | I18: ピーク値 [V] | J18: 半値幅 [nm]
B19: 638 | C19: 0.007 | H19: 100 | I19: =I8 | J19: =I14 | K19: 講義は 200〜1000 µm の範囲を指示しているが，実際は 100 µm と 1000 µm の 2 点。報告書にその旨を書く。
B20: 639 | C20: 0.0069 | H20: 1000 | I20: =J8 | J20: =J14
B21: 640 | C21: 0.0069
B22: 641 | C22: 0.0068
B23: 642 | C23: 0.0067
B24: 643 | C24: 0.0067
B25: 644 | C25: 0.0066
B26: 645 | C26: 0.0064
B27: 646 | C27: 0.0064
B28: 647 | C28: 0.0063
B29: 648 | C29: 0.0062
B30: 649 | C30: 0.006
B31: 650 | C31: 0.006
B32: 651 | C32: 0.0058
... B36: 655 | C36: 0.0051
B39: ※ 2 点しかないため直線の当てはめは行わない。

Sheet 実験3-4_白色LED
B1: 実験3-4 白色 LED のスペクトル測定
B2: 実験3-2 の校正曲線 λ = A x² + B x + C で x を波長に換算した。入射スリット幅 0.1 mm。
B3: 講義は 350〜800 nm の測定を指示しているが，実測範囲は下の「測定範囲」の通り。報告書にその旨を書く。
F5: 解析
F6: 測定範囲 [nm] | G6: =TEXT(MIN(D10:D83),"0")&" 〜 "&TEXT(MAX(D10:D83),"0")
F7: 発光帯ピーク I [V] | G7: =MAX(C10:C83) | H7: 蛍光体による広帯域
F8: 発光帯ピーク波長 [nm] | G8: =INDEX(D10:D83,MATCH(MAX(C10:C83),C10:C83,0))
B9: x [目盛] | C9: I [V] | D9: λ [nm] | F9: 青色ピーク I [V] | G9: =MAX(C50:C83) | H9: LED チップ自身の発光（x≧740 の範囲で探索）
B10: 200 | C10: 0.069 | D10: ='実験3-2_波長校正'!C$12*B10^2+'実験3-2_波長校正'!C$13*B10+'実験3-2_波長校正'!C$14 | F10: 青色ピーク波長 [nm] | G10: =INDEX(D50:D83,MATCH(MAX(C50:C83),C50:C83,0))
B11: 225 | C11: 0.0815 | D11: ='実験3-2_波長校正'!C$12*B11^2+'実験3-2_波長校正'!C$13*B11+'実験3-2_波長校正'!C$14
B12: 250 | C12: 0.0972 | D12: ='実験3-2_波長校正'!C$12*B12^2+'実験3-2_波長校正'!C$13*B12+'実験3-2_波長校正'!C$14 | F12: スペクトル幅（半値幅）
B13: 275 | C13: 0.1134 | D13: ='実験3-2_波長校正'!C$12*B13^2+'実験3-2_波長校正'!C$13*B13+'実験3-2_波長校正'!C$14 | F13: 項目 | G13: 長波長側の山 | H13: 短波長側の山
B14: 300 | C14: 0.1317 | D14: ='実験3-2_波長校正'!C$12*B14^2+'実験3-2_波長校正'!C$13*B14+'実験3-2_波長校正'!C$14 | F14: 背景 I_b [V] | G14: 0 | H14: 0.0312 | I14: 長波長側は 0、短波長側は 2 つの山の谷（x=675, 700 の値）を背景とした
B15: 325 | C15: 0.1485 | D15: ='実験3-2_波長校正'!C$12*B15^2+'実験3-2_波長校正'!C$13*B15+'実験3-2_波長校正'!C$14 | F15: ピーク I_p [V] | G15: =G7 | H15: =G9
B16: 350 | C16: 0.1655 | D16: ='実験3-2_波長校正'!C$12*B16^2+'実験3-2_波長校正'!C$13*B16+'実験3-2_波長校正'!C$14 | F16: 半値 I_h [V] | G16: =G14+(G15-G14)/2 | H16: =H14+(H15-H14)/2
B17: 375 | C17: 0.1795 | D17: ='実験3-2_波長校正'!C$12*B17^2+'実験3-2_波長校正'!C$13*B17+'実験3-2_波長校正'!C$14 | F17: 左交点 x_L [目盛] | G17: =B12+(G16-C12)*(B13-B12)/(C13-C12) | H17: =B56+(H16-C56)*(B57-B56)/(C57-C56) | I17: 内挿区間：長波長側は x=250→275、短波長側は x=752→754
B18: 400 | C18: 0.1903 | D18: ='実験3-2_波長校正'!C$12*B18^2+'実験3-2_波長校正'!C$13*B18+'実験3-2_波長校正'!C$14 | F18: 右交点 x_R [目盛] | G18: =B26+(G16-C26)*(B27-B26)/(C27-C26) | H18: =B74+(H16-C74)*(B75-B74)/(C75-C74) | I18: 内挿区間：長波長側は x=600→625、短波長側は x=795→800
B19: 425 | C19: 0.1966 | D19: ='実験3-2_波長校正'!C$12*B19^2+'実験3-2_波長校正'!C$13*B19+'実験3-2_波長校正'!C$14 | F19: 半値幅 Δλ [nm] | G19: =ABS(('実験3-2_波長校正'!C$12*G17^2+'実験3-2_波長校正'!C$13*G17+'実験3-2_波長校正'!C$14)-('実験3-2_波長校正'!C$12*G18^2+'実験3-2_波長校正'!C$13*G18+'実験3-2_波長校正'!C$14)) | H19: =ABS(('実験3-2_波長校正'!C$12*H17^2+'実験3-2_波長校正'!C$13*H17+'実験3-2_波長校正'!C$14)-('実験3-2_波長校正'!C$12*H18^2+'実験3-2_波長校正'!C$13*H18+'実験3-2_波長校正'!C$14))
B20: 450 | C20: 0.1988 | D20: ='実験3-2_波長校正'!C$12*B20^2+'実験3-2_波長校正'!C$13*B20+'実験3-2_波長校正'!C$14
B21: 475 | C21: 0.1965 | D21: ='実験3-2_波長校正'!C$12*B21^2+'実験3-2_波長校正'!C$13*B21+'実験3-2_波長校正'!C$14
B22: 500 | C22: 0.1894 | D22: ='実験3-2_波長校正'!C$12*B22^2+'実験3-2_波長校正'!C$13*B22+'実験3-2_波長校正'!C$14
B23: 525 | C23: 0.1784 | D23: ='実験3-2_波長校正'!C$12*B23^2+'実験3-2_波長校正'!C$13*B23+'実験3-2_波長校正'!C$14
B24: 550 | C24: 0.1623 | D24: ='実験3-2_波長校正'!C$12*B24^2+'実験3-2_波長校正'!C$13*B24+'実験3-2_波長校正'!C$14
B25: 575 | C25: 0.1412 | D25: ='実験3-2_波長校正'!C$12*B25^2+'実験3-2_波長校正'!C$13*B25+'実験3-2_波長校正'!C$14
B26: 600 | C26: 0.1109 | D26: ='実験3-2_波長校正'!C$12*B26^2+'実験3-2_波長校正'!C$13*B26+'実験3-2_波長校正'!C$14
B27: 625 | C27: 0.0778 | D27: ='実験3-2_波長校正'!C$12*B27^2+'実験3-2_波長校正'!C$13*B27+'実験3-2_波長校正'!C$14
B28: 650 | C28: 0.0472 | D28: ='実験3-2_波長校正'!C$12*B28^2+'実験3-2_波長校正'!C$13*B28+'実験3-2_波長校正'!C$14
B29: 675 | C29: 0.0312 | D29: ='実験3-2_波長校正'!C$12*B29^2+'実験3-2_波長校正'!C$13*B29+'実験3-2_波長校正'!C$14
B30: 700 | C30: 0.0312 | D30: ='実験3-2_波長校正'!C$12*B30^2+'実験3-2_波長校正'!C$13*B30+'実験3-2_波長校正'!C$14
B31: 702 | C31: 0.0316 | D31: ='実験3-2_波長校正'!C$12*B31^2+'実験3-2_波長校正'!C$13*B31+'実験3-2_波長校正'!C$14
... B83: 840 | C83: 0.0132 | D83: ='実験3-2_波長校正'!C$12*B83^2+'実験3-2_波長校正'!C$13*B83+'実験3-2_波長校正'!C$14

Sheet week_1
B3: x0=50mm | C3: L=150mm
B5: Na(オレンジ) | C5: x1[mm] | D5: x | E5: θ | F5: λ[nm]
B6: 左 | C6: 95
B7: 中 | C7: 97
B8: 右 | C8: 99
B12: 水銀ランプ | C12: x1[mm] | D12: x | E12: θ | F12: λ[nm]
B13: 左 | C13: 95.2
B14: 中 | C14: 98.1
B15: 右 | C15: 100.4
B18: Hg
B19: オレンジ | C19: x1[mm] | D19: x | E19: θ | F19: λ[nm]
B20: 左 | C20: 87.5
B21: 中 | C21: 89
B22: 右 | C22: 90.9
B26: 緑 | C26: x1[mm] | D26: x | E26: θ | F26: λ[nm]
B27: 左 | C27: 74.2
B28: 中 | C28: 75.5
B29: 右 | C29: 77
B34: 青 | C34: x1[mm] | D34: x | E34: θ | F34: λ[nm]
B35: 左 | C35: 37.1
B36: 中 | C36: 38.2
B37: 右 | C37: 39.2
B42: Cd
B43: 赤
B44: 真ん中 | C44: 12.5mm
B46: 緑
B47: 左 | C47: 52
B48: 中 | C48: 54.5
B49: 右 | C49: 57
B51: 水色の左
B52: 左 | C52: 35.5
B53: 中 | C53: 37
B54: 右 | C54: 40.5
B57: 青
B58: 左 | C58: 35.6
B61: Cd
B62: L=150mm | C62: x | D62: δ0 | E62: n(屈折率)
B63: 赤 | C63: 136
B64: 緑 | C64: 128
B65: 水色 | C65: 127
...
